Workbook
Name Teams: #REF!
Name Teams: 'PI Commitments'!$AH$3:$AH$93

Sheet Sheet1
A1: Match | B1: ID | C1: Title | D1: Work Item Type | E1: Assigned To | F1: Time Criticality | G1: Priority | H1: Effort | I1: Target Date | J1: State | K1: Tags | L1: Area Path
A2: =VLOOKUP(B2,'PI Commitments'!#REF!,1,FALSE) -> #REF! | B2: 165196 | C2: Generation of manual JSON files for Langhorne | D2: Feature | E2: Polannagari, Govardhan | F2: 0.5 | G2: 2 | H2: 2 | I2: 43686 | J2: Closed | K2: Langhorne | L2: GlobalREApps\Debt
A3: =VLOOKUP(B3,'PI Commitments'!#REF!,1,FALSE) -> #REF! | B3: 65960 | C3: EMEA data for Dublin Bank | D3: Feature | E3: Cole, Lisa | F3: 8 | G3: 1 | H3: 1 | I3: 43694 | J3: Closed | K3: _Ready; CLS; OneSource | L3: GlobalREApps\Debt\LMW
A4: =VLOOKUP(B4,'PI Commitments'!#REF!,1,FALSE) -> #REF! | B4: 127851 | C4: Real-time data processing new loans | D4: Feature | E4: Talluru, Praveena | F4: 4 | G4: 1 | H4: 2 | I4: 43694 | J4: Closed | K4: _Ready; CLS | L4: GlobalREApps\Debt\LMW
A5: =VLOOKUP(B5,'PI Commitments'!#REF!,1,FALSE) -> #REF! | B5: 49326 | C5: Final Concluded Property Value/LTV in Feed From Backshop to LMW | D5: Feature | E5: Mitchell, Aj | F5: 3 | G5: 1 | H5: 3 | I5: 43694 | J5: Closed | K5: _Ready; LMW | L5: GlobalREApps\Debt\LMW
A6: =VLOOKUP(B6,'PI Commitments'!#REF!,1,FALSE) -> #REF! | B6: 133868 | C6: CLS Implementation for CECL Enhancements | D6: Feature | E6: Montoya, Fabio | F6: 1.75 | G6: 1 | H6: 4 | I6: 43694 | J6: Closed | K6: _Ready; CECL; CLS | L6: GlobalREApps\Debt\CLS
A7: =VLOOKUP(B7,'PI Commitments'!#REF!,1,FALSE) -> #REF! | B7: 133865 | C7: Backshop Implementation for CECL Enhancements | D7: Feature | E7: Montoya, Fabio | F7: 1.667 | G7: 1 | H7: 1 | I7: 43694 | J7: Closed | K7: _Ready; Backshop; Backshop_Met; CECL | L7: GlobalREApps\Debt\CLS
A8: =VLOOKUP(B8,'PI Commitments'!#REF!,1,FALSE) -> #REF! | B8: 119226 | C8: Client Reporting : Beneficial Borrower Report feed to SSB for CMIF loans | D8: Feature | E8: Bose, Siddhartha | F8: 1.2 | G8: 1 | H8: 5 | I8: 43694 | J8: Closed | K8: _Ready; MIS | L8: GlobalREApps\Debt\MIS
A9: =VLOOKUP(B9,'PI Commitments'!#REF!,1,FALSE) -> #REF! | B9: 49574 | C9: Automatically generate and attach the FTM Compare Report to the the "FTM Review Approved" notification | D9: Feature | E9: Mitchell, Aj | F9: 1 | G9: 1 | H9: 6 | I9: 43694 | J9: Closed | K9: _Ready; Backshop | L9: GlobalREApps\Debt
A10: =VLOOKUP(B10,'PI Commitments'!#REF!,1,FALSE) -> #REF! | B10: 156184 | C10: Script Request - Loan 702826 Rating and Valuation Review - Loan Commentary | D10: Feature | E10: Ramaraj, Vinoth | F10: 8 | G10: 2 | H10: 1 | I10: 43694 | J10: Closed | K10: _Ready; LMW | L10: GlobalREApps\Debt
A11: =VLOOKUP(B11,'PI Commitments'!#REF!,1,FALSE) -> #REF! | B11: 156201 | C11: Data Script request to update mortgage rating grade for loan 540151 | D11: Feature | E11: Ramaraj, Vinoth | F11: 8 | G11: 2 | H11: 1 | I11: 43694 | J11: Closed | K11: _Ready; LMW | L11: GlobalREApps\Debt
A12: =VLOOKUP(B12,'PI Commitments'!#REF!,1,FALSE) -> #REF! | B12: 160978 | C12: CECL - Publish MetLife Internal Ratings in Loan Rating file | D12: Feature | E12: Montoya, Fabio | F12: 4 | G12: 2 | H12: 1 | I12: 43694 | J12: Closed | K12: _Ready; CECL; MIS | L12: GlobalREApps\Debt\CLS
A13: =VLOOKUP(B13,'PI Commitments'!#REF!,1,FALSE) -> #REF! | B13: 162295 | C13: BHF: new compliance fields for ADW | D13: Feature | E13: Cole, Lisa | F13: 3 | G13: 2 | H13: 1 | I13: 43694 | J13: Closed | K13: _Ready; CLS | L13: GlobalREApps\Debt
... A29: =VLOOKUP(B29,'PI Commitments'!#REF!,1,FALSE) -> #REF! | B29: 151392 | C29: Change GA Reportable to Delegated Authority Reportable in LMW | D29: Feature | E29: Mitchell, Aj | F29: 1 | G29: 3 | H29: 1 | I29: 43694 | J29: Closed | K29: _Ready; LMW | L29: GlobalREApps\Debt
A30: =VLOOKUP(B30,'PI Commitments'!#REF!,1,FALSE) -> #REF! | B30: 169146 | C30: Loan Search - Report run and export issues | D30: Feature | E30: Polannagari, Govardhan | G30: 1 | I30: 43701 | J30: Closed | K30: Debt; High Risk; Loan Search; MIS | L30: GlobalREApps\Debt\MIS
A31: =VLOOKUP(B31,'PI Commitments'!#REF!,1,FALSE) -> #REF! | B31: 134972 | C31: BHF : Incorrect REI Market Area & attributes in MIS and upstream systems | D31: Feature | E31: Polannagari, Govardhan | F31: 2 | G31: 1 | H31: 4 | I31: 43701 | J31: Closed | K31: _Ready; MIS | L31: GlobalREApps\Debt\MIS
A32: =VLOOKUP(B32,'PI Commitments'!#REF!,1,FALSE) -> #REF! | B32: 164350 | C32: Subledger data break - Fix for loan#703141 | D32: Feature | E32: Polannagari, Govardhan | G32: 2 | I32: 43701 | J32: Closed | K32: MIS; Problem | L32: GlobalREApps\Debt\MIS
A33: =VLOOKUP(B33,'PI Commitments'!#REF!,1,FALSE) -> #REF! | B33: 145409 | C33: Market Value : Caps and Floors Error | D33: Feature | E33: Polannagari, Govardhan | F33: 4 | G33: 2 | H33: 1 | I33: 43701 | J33: Closed | K33: _Ready; Market Value; MIS | L33: GlobalREApps\Debt\MIS
A34: =VLOOKUP(B34,'PI Commitments'!#REF!,1,FALSE) -> #REF! | B34: 142570 | C34: MARS - Step rate loans incorrectly categorized as ARMs in MIS due to EDM field MetLifeInterestType consumption derivation logic changed. | D34: Feature | E34: Polannagari, Govardhan | F34: 3 | G34: 2 | H34: 2 | I34: 43701 | J34: Closed | K34: _Ready; MARS; MIS | L34: GlobalREApps\Debt\MIS
A35: =VLOOKUP(B35,'PI Commitments'!#REF!,1,FALSE) -> #REF! | B35: 146115 | C35: MIS_PAMTransExtract Load Batch Job update | D35: Feature | E35: Polannagari, Govardhan | F35: 2.5 | G35: 2 | H35: 2 | I35: 43701 | J35: Closed | K35: _Ready; MIS | L35: GlobalREApps\Debt
A36: =VLOOKUP(B36,'PI Commitments'!#REF!,1,FALSE) -> #REF! | B36: 159170 | C36: MIS : Company name issue - AVIVA Life & Pensions UK Limited | D36: Feature | E36: Polannagari, Govardhan | F36: 2 | G36: 2 | H36: 2 | I36: 43701 | J36: Closed | K36: MIS; Technical Debt | L36: GlobalREApps\Debt\MIS
A37: =VLOOKUP(B37,'PI Commitments'!#REF!,1,FALSE) -> #REF! | B37: 161675 | C37: MIS Veracode Findings 2019 - High Flaws | D37: Feature | E37: Polannagari, Govardhan | F37: 2 | G37: 2 | H37: 3 | I37: 43701 | J37: Closed | K37: MIS; Technical Debt; Veracode | L37: GlobalREApps\Debt\MIS
A38: =VLOOKUP(B38,'PI Commitments'!#REF!,1,FALSE) -> #REF! | B38: 146600 | C38: MIS Asset File is missing country sub div codes | D38: Feature | E38: Polannagari, Govardhan | F38: 1.333 | G38: 2 | H38: 3 | I38: 43701 | J38: Closed | K38: _Ready; EDM Sub Div Code; MIS | L38: GlobalREApps\Debt
A39: =VLOOKUP(B39,'PI Commitments'!#REF!,1,FALSE) -> #REF! | B39: 158916 | C39: MARS : MIS consumption of TDR fields | D39: Feature | E39: Polannagari, Govardhan | F39: 1.333 | G39: 2 | H39: 3 | I39: 43701 | J39: Closed | K39: _Ready; MARS; MIS | L39: GlobalREApps\Debt\MIS
A40: =VLOOKUP(B40,'PI Commitments'!#REF!,1,FALSE) -> #REF! | B40: 166747 | C40: Incorrect Property Type - Schedule B | D40: Feature | E40: Polannagari, Govardhan | F40: 7 | G40: 1 | H40: 1 | I40: 43722 | J40: Active | K40: _Ready; MIS; Sched B | L40: GlobalREApps\Debt\MIS
A41: =VLOOKUP(B41,'PI Commitments'!#REF!,1,FALSE) -> #REF! | B41: 173796 | C41: MIS Domain Mapping - missing Country Admin Subdivision | D41: Feature | E41: Polannagari, Govardhan | F41: 3 | G41: 1 | H41: 1 | I41: 43722 | J41: New | K41: _Ready; MIS | L41: GlobalREApps\Debt
A42: =VLOOKUP(B42,'PI Commitments'!#REF!,1,FALSE) -> #REF! | B42: 119203 | C42: Data at rest encryption | D42: Feature | E42: Polannagari, Govardhan | F42: 2.25 | G42: 1 | H42: 2 | I42: 43722 | J42: Active | K42: _Ready; MIS | L42: GlobalREApps\Debt\MIS
A43: =VLOOKUP(B43,'PI Commitments'!#REF!,1,FALSE) -> #REF! | B43: 87842 | C43: Ethical Hack: Remediate PrimeOn - medium flaws – Phase 3 | D43: Feature | E43: Talluru, Praveena | F43: 1.6 | G43: 1 | H43: 5 | I43: 43722 | J43: Active | K43: _Ready; LMW | L43: GlobalREApps\Debt\LMW
A44: =VLOOKUP(B44,'PI Commitments'!#REF!,1,FALSE) -> #REF! | B44: 113622 | C44: AG : Servicer compare report enhancement | D44: Feature | E44: Polannagari, Govardhan | F44: 1.2 | G44: 1 | H44: 5 | I44: 43722 | J44: Active | K44: _Ready; AG; MIS | L44: GlobalREApps\Debt\MIS
... A61: =VLOOKUP(B61,'PI Commitments'!#REF!,1,FALSE) -> #REF! | B61: 122060 | C61: MIS : Portfolio Exposure Data Dump Report Enhancement | D61: Feature | E61: Polannagari, Govardhan | F61: 0.778 | G61: 2 | H61: 9 | I61: 43722 | J61: Active | K61: _Ready; MIS | L61: GlobalREApps\Debt\MIS
A62: =VLOOKUP(B62,'PI Commitments'!#REF!,1,FALSE) -> #REF! | B62: 155876 | C62: Backshop Field Extract for MIST | D62: Feature | E62: Anderson, William | G62: 2 | H62: 8 | I62: 43728 | J62: Active | K62: Backshop | L62: GlobalREApps\Debt\Backshop
A63: =VLOOKUP(B63,'PI Commitments'!#REF!,1,FALSE) -> #REF! | B63: 162136 | C63: FTP Activities for Backshop Field Extract for MIST | D63: Feature | E63: Anderson, William | G63: 2 | H63: 3 | I63: 43728 | J63: New | K63: Backshop; Backshop_Met | L63: GlobalREApps\Debt
A64: =VLOOKUP(B64,'PI Commitments'!#REF!,1,FALSE) -> #REF! | B64: 156000 | C64: Revisions and additions to the REI Market Area reference data_Backshop | D64: Feature | E64: Mitchell, Aj | F64: 3 | G64: 2 | H64: 2 | I64: 43728 | J64: Active | K64: _Ready; Backshop | L64: GlobalREApps\Debt
A65: =VLOOKUP(B65,'PI Commitments'!#REF!,1,FALSE) -> #REF! | B65: 150715 | C65: Increase the Commitment Fee (BPS) field size from 1 decimal to 2 decimal places in MIM notification | D65: Feature | E65: Anderson, William | F65: 3 | G65: 2 | H65: 1 | I65: 43728 | J65: New | K65: _Ready; Backshop | L65: GlobalREApps\Debt
A66: =VLOOKUP(B66,'PI Commitments'!#REF!,1,FALSE) -> #REF! | B66: 160505 | C66: BackShop Audit file generation delays | D66: Feature | E66: Anderson, William | F66: 1.333 | G66: 2 | H66: 3 | I66: 43728 | J66: New | K66: Backshop; Backshop_Met; Japan Item | L66: GlobalREApps\Debt
A67: =VLOOKUP(B67,'PI Commitments'!#REF!,1,FALSE) -> #REF! | B67: 113634 | C67: Calculate Relative Value for Comm and AG Assets | D67: Feature | E67: Mitchell, Aj | F67: 1.167 | G67: 2 | H67: 6 | I67: 43728 | J67: Active | K67: _Spike; Backshop; Backshop_Met | L67: GlobalREApps\Debt
A68: =VLOOKUP(B68,'PI Commitments'!#REF!,1,FALSE) -> #REF! | B68: 61014 | C68: Capitalized Interest Transactions | D68: Feature | E68: Cole, Lisa | F68: 0.8333 | G68: 2 | H68: 6 | I68: 43728 | J68: New | K68: _Spike; CLS | L68: GlobalREApps\Debt
A69: =VLOOKUP(B69,'PI Commitments'!#REF!,1,FALSE) -> #REF! | B69: 160836 | C69: Insert New REI Market Areas and revise several existing | D69: Feature | E69: Polannagari, Govardhan | G69: 2 | I69: 43729 | J69: New | K69: LMW | L69: GlobalREApps\Debt
A70: =VLOOKUP(B70,'PI Commitments'!#REF!,1,FALSE) -> #REF! | B70: 143186 | C70: SFR loans to CLS from Midland | D70: Feature | E70: Lopez, Ascension | F70: 1.333 | G70: 1 | H70: 4 | I70: 43735 | J70: New | K70: _Ready; CLS | L70: GlobalREApps\Debt
A71: =VLOOKUP(B71,'PI Commitments'!#REF!,1,FALSE) -> #REF! | B71: 161827 | C71: Discovery: Move calculation of price from MIS to LMW | D71: Feature | E71: Mitchell, Aj | F71: 2.667 | G71: 1 | H71: 3 | I71: 43736 | J71: New | K71: _Spike; LMW | L71: GlobalREApps\Debt
...

Sheet Start Here
B1: PI Sprint # | C1: Cloud Services Sprint # | D1: Start Date | E1: End Date | G1: Release | H1: PI-Sprint | I1: Env | J1: Abbrev | K1: Start Date | L1: End Date | N1: Red = Holiday
A2: PI-8 Sprint Dates | B2: 5 | C2: 96 | D2: 44643 | E2: 44656 | G2: April 2022 | H2: (PI-8) 3-5 | I2: DEV | J2: DA | K2: =K5-47 -> 44620 | L2: =K5-22 -> 44645 | O2: S | P2: M | Q2: T | R2: W | S2: T | T2: F | U2: S | X2: S | Y2: M | Z2: T | AA2: W | AB2: T | AC2: F | AD2: S
B3: 6 | C3: =C2+1 -> 97 | D3: 44657 | E3: 44670 | H3: (PI-8) 5-6 | I3: SIT/INT | J3: SA | K3: =K5-19 -> 44648 | L3: =K5-15 -> 44652 | N3: April | T3: 1 | U3: 2 | W3: May | X3: 1 | Y3: 2 | Z3: 3 | AA3: 4 | AB3: 5 | AC3: 6 | AD3: 7
A4: PI-9 Sprint Dates | B4: 1 | C4: =C3+1 -> 98 | D4: =D3+14 -> 44671 | E4: =E3+14 -> 44684 | H4: (PI-8) 6 | I4: UAT/QA | J4: UA | K4: =K5-12 -> 44655 | L4: =K5-4 -> 44663 | T4: SA, UA, DY | U4: SA, UA, DY | X4: SY,UY | Y4: UY,DU | Z4: UY,DU | AA4: UY,DU | AB4: UY,DU | AC4: UY,DU | AD4: UY,DU
B5: 2 | C5: =C4+1 -> 99 | D5: =D4+14 -> 44685 | E5: =E4+14 -> 44698 | H5: (PI-9) 1 | I5: PROD+DR | J5: PA | K5: 44667 | O5: 3 | P5: 4 | Q5: 5 | R5: 6 | S5: 7 | T5: 8 | U5: 9 | X5: 8 | Y5: 9 | Z5: 10 | AA5: 11 | AB5: 12 | AC5: 13 | AD5: 14
B6: 3 | C6: =C5+1 -> 100 | D6: =D5+14 -> 44699 | E6: =E5+14 -> 44712 | G6: May 2022 | H6: (PI-8) 5-6 (PI-9) 1 | I6: DEV | J6: DY | K6: =K9-47 -> 44648 | L6: =K9-22 -> 44673 | O6: SA, UA, DY | P6: UA, DY | Q6: UA, DY | R6: UA, DY | S6: UA, DY | T6: UA, DY | U6: UA, DY | X6: UY,DU | Y6: UY,DU | Z6: UY,DU | AA6: PY,DU | AB6: PY,DU | AC6: PY,DU | AD6: PY,DU
B7: 4 | C7: =C6+1 -> 101 | D7: =D6+14 -> 44713 | E7: =E6+14 -> 44726 | H7: (PI-9) 1 | I7: SIT/INT | J7: SY | K7: =K9-19 -> 44676 | L7: =K9-15 -> 44680 | O7: 10 | P7: 11 | Q7: 12 | R7: 13 | S7: 14 | T7: 15 | U7: 16 | X7: 15 | Y7: 16 | Z7: 17 | AA7: 18 | AB7: 19 | AC7: 20 | AD7: 21
B8: 5 | C8: =C7+1 -> 102 | D8: =D7+14 -> 44727 | E8: =E7+14 -> 44740 | H8: (PI-9) 1-2 | I8: UAT/QA | J8: UY | K8: =K9-12 -> 44683 | L8: =K9-4 -> 44691 | O8: UA, DY | P8: UA, DY | Q8: UA, DY | R8: PA,DY | S8: PA,DY | T8: PA,DY | U8: PA,DY | X8: DU | Y8: DU | Z8: DU | AA8: DU | AB8: DU | AC8: DU | AD8: DU
B9: 6 | C9: =C8+1 -> 103 | D9: =D8+14 -> 44741 | E9: =E8+14 -> 44754 | H9: (PI-9) 3 | I9: PROD+DR | J9: PY | K9: 44695 | O9: 17 | P9: 18 | Q9: 19 | R9: 20 | S9: 21 | T9: 22 | U9: 23 | X9: 22 | Y9: 23 | Z9: 24 | AA9: 25 | AB9: 26 | AC9: 27 | AD9: 28
A10: PI-10 | B10: 1 | C10: =C9+1 -> 104 | D10: =D9+14 -> 44755 | E10: =E9+14 -> 44768 | G10: June 2022 | H10: (PI-9) 1-3 | I10: DEV | J10: DU | K10: =K13-47 -> 44683 | L10: =K13-22 -> 44708 | O10: DY | P10: DY | Q10: DY | R10: DY | S10: DY | T10: DY,SY | U10: DY,SY | X10: DU | Y10: DU | Z10: DU | AA10: DU | AB10: DU | AC10: DU,SU | AD10: DU,SU
B11: 2 | C11: =C10+1 -> 105 | D11: =D10+14 -> 44769 | E11: =E10+14 -> 44782 | H11: (PI-9) 3 | I11: SIT/INT | J11: SU | K11: =K13-19 -> 44711 | L11: =K13-15 -> 44715 | O11: 24 | P11: 25 | Q11: 26 | R11: 27 | S11: 28 | T11: 29 | U11: 30 | X11: 29 | Y11: 30 | Z11: 31
H12: (PI-9) 3-4 | I12: UAT/QA | J12: UU | K12: =K13-12 -> 44718 | L12: =K13-4 -> 44726 | O12: DY,SY | P12: SY | Q12: SY | R12: SY | S12: SY | T12: SY,UY | U12: SY,UY | X12: DU,SU | Y12: SU,DL | Z12: SU,DL
H13: (PI-8) 4 | I13: PROD+DR | J13: PU | K13: 44730
G14: July 2022 | H14: (PI-8) 3-5 | I14: DEV | J14: DL | K14: =K17-47 -> 44711 | L14: =K17-22 -> 44736
H15: (PI-8) 5-6 | I15: SIT/INT | J15: SL | K15: =K17-19 -> 44739 | L15: =K17-15 -> 44743
H16: (PI-8) 6 | I16: UAT/QA | J16: UL | K16: =K17-12 -> 44746 | L16: =K17-4 -> 44754 | O16: S | P16: M | Q16: T | R16: W | S16: T | T16: F | U16: S | X16: S | Y16: M | Z16: T | AA16: W | AB16: T | AC16: F | AD16: S
D17: Planned | E17: Available=Actual - Holidays | H17: (PI-9) 1 | I17: PROD+DR | J17: PL | K17: 44758 | N17: June | R17: 1 | S17: 2 | T17: 3 | U17: 4 | W17: July | AC17: 1 | AD17: 2
D18: 74 | G18: Aug 2022 | H18: (PI-8) 5-6 (PI-9) 1 | I18: DEV | J18: DG | K18: =K21-47 -> 44746 | L18: =K21-22 -> 44771 | R18: SU,DL | S18: SU,DL | T18: SU,UU,DL | U18: SU,UU,DL | AC18: SL,UL | AD18: SL,UL
H19: (PI-9) 1-2 | I19: SIT/INT | J19: SG | K19: =K21-19 -> 44774 | L19: =K21-15 -> 44778 | O19: 5 | P19: 6 | Q19: 7 | R19: 8 | S19: 9 | T19: 10 | U19: 11 | X19: 3 | Y19: 4 | Z19: 5 | AA19: 6 | AB19: 7 | AC19: 8 | AD19: 9
H20: (PI-9) 2 | I20: UAT/QA | J20: UG | K20: =K21-12 -> 44781 | L20: =K21-4 -> 44789 | O20: SU,UU,DL | P20: UU,DL | Q20: UU,DL | R20: UU,DL | S20: UU,DL | T20: UU,DL | U20: UU,DL | X20: SL,UL | Y20: UL,DG | Z20: UL,DG | AA20: UL,DG | AB20: UL,DG | AC20: UL,DG | AD20: UL,DG
H21: (PI-9) 3 | I21: PROD+DR | J21: PG | K21: 44793 | O21: 12 | P21: 13 | Q21: 14 | R21: 15 | S21: 16 | T21: 17 | U21: 18 | X21: 10 | Y21: 11 | Z21: 12 | AA21: 13 | AB21: 14 | AC21: 15 | AD21: 16
O22: UU,DL | P22: UU,DL | Q22: UU,DL | R22: PU,DL | S22: PU,DL | T22: PU,DL | U22: PU,DL | X22: UL,DG | Y22: UL,DG | Z22: UL,DG | AA22: PL,DG | AB22: PL,DG | AC22: PL,DG | AD22: PL,DG
G23: Abbreviations | H23: Environments | I23: Months | O23: 19 | P23: 20 | Q23: 21 | R23: 22 | S23: 23 | T23: 24 | U23: 25 | X23: 17 | Y23: 18 | Z23: 19 | AA23: 20 | AB23: 21 | AC23: 22 | AD23: 23
D24: Ninjas | E24: Samurais | G24: (Legend) | I24: J = January | K24: L = July | O24: DL | P24: DL | Q24: DL | R24: DL | S24: DL | T24: DL,SL | U24: DL,SL | X24: DG | Y24: DG | Z24: DG | AA24: DG | AB24: DG | AC24: DG | AD24: DG
A25: 1 | B25: 44671 | C25: 44684 | D25: sprint 59 | E25: Sprint 98 | H25: D = Dev | I25: F = February | K25: G = August | O25: 26 | P25: 27 | Q25: 28 | R25: 29 | S25: 30 | X25: 24 | Y25: 25 | Z25: 26 | AA25: 27 | AB25: 28 | AC25: 29 | AD25: 30
A26: 2 | B26: 44685 | C26: 44698 | D26: sprint 60 | E26: Sprint 99 | H26: S = SIT/INT | I26: M = March | K26: S = September | O26: DL,SL | P26: SL | Q26: SL | R26: SL | S26: SL | X26: DG | Y26: DG | Z26: DG | AA26: DG | AB26: DG | AC26: DG,SG | AD26: DG,SG
A27: 3 | B27: 44699 | C27: 44712 | D27: sprint 61 | E27: Sprint 100 | H27: U = UAT/QA | I27: A = April | K27: O = October | X27: 31
A28: 4 | B28: 44713 | C28: 44726 | D28: sprint 62 | E28: Sprint 101 | H28: P = PROD+DR | I28: Y = May | K28: N = November | X28: DG,SG
A29: 5 | B29: 44727 | C29: 44740 | D29: sprint 63 | E29: Sprint 102 | I29: U = June | K29: D = December
A30: 6 | B30: 44741 | C30: 44754 | D30: sprint 64 | E30: Sprint 103 | O30: S | P30: M | Q30: T | R30: W | S30: T | T30: F | U30: S
N31: August | P31: 1 | Q31: 2 | R31: 3 | S31: 4 | T31: 5 | U31: 6
H32: =E4-D4+1 -> 14 | I32: =E7-D7+1 -> 14
H33: =K10-D4+1 -> 13 | I33: =L12-E7+1 -> 1 | O33: 7 | P33: 8 | Q33: 9 | R33: 10 | S33: 11 | T33: 12 | U33: 13
A34: swapna | B34: 44572 | C34: 1 | H34: =CEILING((1-H33/H32)*5,1) -> 1 | I34: =CEILING((1-I33/I32)*5,1) -> 5
A35: abhijith | O35: 14 | P35: 15 | Q35: 16 | R35: 17 | S35: 18 | T35: 19 | U35: 20
A36: Krishna
A37: Prasob | B37: 1/24,2/18 | C37: 2 | O37: 21 | P37: 22 | Q37: 23 | R37: 24 | S37: 25 | T37: 26 | U37: 27
A38: lokesh | B38: 1/27,28; 2/14,15; | C38: 4
A39: manoj | O39: 28 | P39: 29 | Q39: 30 | R39: 31
A40: smba | B40: 1/17,18; march 5 days | C40: 7
...

Sheet Resource Planning
B1: End Date | E1: 44657 | F1: =E1+14 -> 44671 | G1: =F1+14 -> 44685 | H1: =G1+14 -> 44699 | I1: =H1+14 -> 44713 | J1: =I1+14 -> 44727 | K1: =J1+14 -> 44741 | N1: Black Widow
C2: Name | D2: Team | E2: Allotment | F2: S1 | G2: S2 | H2: S3 | I2: S4 | J2: S5 | K2: S6 | N2: Captain America | R2: Commit
B3: AJ | C3: Abhijith Jayakumar | D3: The Ninjas | E3: 1 | F3: =(1-(COUNTIF($AE$10:$AQ$23, $B3)/10))*$E3 -> 0.9 | G3: =(1-(COUNTIF($AE$24:$AQ$37, $B3)/10))*$E3 -> 1 | H3: =(1-(COUNTIF($AE$38:$AQ$51, $B3)/10))*$E3 -> 0.9 | I3: =(1-(COUNTIF($AE$52:$AQ$65, $B3)/10))*$E3 -> 1 | J3: =(1-(COUNTIF($AE$66:$AQ$79, $B3)/10))*$E3 -> 1 | K3: =(1-(COUNTIF($AE$80:$AQ$93, $B3)/10))*$E3 -> 1 | L3: =SUM(F3:K3)*8 -> 46.4 | M3: =SUM(F3:K3) *8 -> 46.4 | N3: Hulk | R3: Resolved
B4: JB | C4: Jagadeesan Balasubramanian | D4: The Ninjas | E4: 1 | F4: =(1-(COUNTIF($AE$10:$AQ$23, $B4)/10))*$E4 -> 1 | G4: =(1-(COUNTIF($AE$24:$AQ$37, $B4)/10))*$E4 -> 1 | H4: =(1-(COUNTIF($AE$38:$AQ$51, $B4)/10))*$E4 -> 0.9 | I4: =(1-(COUNTIF($AE$52:$AQ$65, $B4)/10))*$E4 -> 1 | J4: =(1-(COUNTIF($AE$66:$AQ$79, $B4)/10))*$E4 -> 1 | K4: =(1-(COUNTIF($AE$80:$AQ$93, $B4)/10))*$E4 -> 0.9 | L4: =SUM(F4:K4)*8 -> 46.4 | M4: =SUM(F4:K4) *8 -> 46.4 | N4: Ironman | R4: Stretch
A5: 11 | B5: KCK | C5: Krishna chandar kandula | D5: The Ninjas | E5: 1 | F5: =(1-(COUNTIF($AE$10:$AQ$23, $B5)/10))*$E5 -> 0.9 | G5: =(1-(COUNTIF($AE$24:$AQ$37, $B5)/10))*$E5 -> 1 | H5: =(1-(COUNTIF($AE$38:$AQ$51, $B5)/10))*$E5 -> 1 | I5: =(1-(COUNTIF($AE$52:$AQ$65, $B5)/10))*$E5 -> 1 | J5: =(1-(COUNTIF($AE$66:$AQ$79, $B5)/10))*$E5 -> 1 | K5: =(1-(COUNTIF($AE$80:$AQ$93, $B5)/10))*$E5 -> 1 | L5: =SUM(F5:K5)*8 -> 47.2 | M5: =SUM(F5:K5) *8 -> 47.2 | N5: Vision | R5: Vendor
B6: KN | C6: Krishnaraj Nagaraj | D6: The Ninjas | E6: 0.9 | F6: =(1-(COUNTIF($AE$10:$AQ$23, $B6)/10))*$E6 -> 0.9 | G6: =(1-(COUNTIF($AE$24:$AQ$37, $B6)/10))*$E6 -> 0.9 | H6: =(1-(COUNTIF($AE$38:$AQ$51, $B6)/10))*$E6 -> 0.9 | I6: =(1-(COUNTIF($AE$52:$AQ$65, $B6)/10))*$E6 -> 0.9 | J6: =(1-(COUNTIF($AE$66:$AQ$79, $B6)/10))*$E6 -> 0.9 | K6: =(1-(COUNTIF($AE$80:$AQ$93, $B6)/10))*$E6 -> 0.9 | L6: =SUM(F6:K6)*8 -> 43.2 | M6: =SUM(F6:K6) *8 -> 43.2
B7: LS | C7: Lokeshwaran Sankar | D7: The Ninjas | E7: 1 | F7: =(1-(COUNTIF($AE$10:$AQ$23, $B7)/10))*$E7 -> 0.9 | G7: =(1-(COUNTIF($AE$24:$AQ$37, $B7)/10))*$E7 -> 1 | H7: =(1-(COUNTIF($AE$38:$AQ$51, $B7)/10))*$E7 -> 1 | I7: =(1-(COUNTIF($AE$52:$AQ$65, $B7)/10))*$E7 -> 1 | J7: =(1-(COUNTIF($AE$66:$AQ$79, $B7)/10))*$E7 -> 1 | K7: =(1-(COUNTIF($AE$80:$AQ$93, $B7)/10))*$E7 -> 1 | L7: =SUM(F7:K7)*8 -> 47.2 | M7: =SUM(F7:K7) *8 -> 47.2
B8: MM | C8: Manoj Madhavan | D8: The Ninjas | E8: 1 | F8: =(1-(COUNTIF($AE$10:$AQ$23, $B8)/10))*$E8 -> 0.7 | G8: =(1-(COUNTIF($AE$24:$AQ$37, $B8)/10))*$E8 -> 0.9 | H8: =(1-(COUNTIF($AE$38:$AQ$51, $B8)/10))*$E8 -> 0.9 | I8: =(1-(COUNTIF($AE$52:$AQ$65, $B8)/10))*$E8 -> 1 | J8: =(1-(COUNTIF($AE$66:$AQ$79, $B8)/10))*$E8 -> 1 | K8: =(1-(COUNTIF($AE$80:$AQ$93, $B8)/10))*$E8 -> 1 | L8: =SUM(F8:K8)*8 -> 44 | M8: =SUM(F8:K8) *8 -> 44 | S8: SAMURAIS | AE8: NINJAS
B9: MHA | C9: Meraj Husen Ansari | D9: The Ninjas | E9: 1 | F9: =(1-(COUNTIF($AE$10:$AQ$23, $B9)/10))*$E9 -> 0.9 | G9: =(1-(COUNTIF($AE$24:$AQ$37, $B9)/10))*$E9 -> 1 | H9: =(1-(COUNTIF($AE$38:$AQ$51, $B9)/10))*$E9 -> 1 | I9: =(1-(COUNTIF($AE$52:$AQ$65, $B9)/10))*$E9 -> 1 | J9: =(1-(COUNTIF($AE$66:$AQ$79, $B9)/10))*$E9 -> 1 | K9: =(1-(COUNTIF($AE$80:$AQ$93, $B9)/10))*$E9 -> 1 | L9: =SUM(F9:K9)*8 -> 47.2 | M9: =SUM(F9:K9) *8 -> 47.2 | S9: AN | T9: AM | U9: ASU | V9: DF | W9: JR | X9: KN | Y9: MN | Z9: RB | AA9: VS | AB9: VG | AC9: AC | AD9: VA | AE9: AJ | AF9: JB | AG9: KCK | AH9: KN | AI9: LS | AJ9: MM | AK9: MHA | AL9: PN | AM9: SSRP | AN9: SS | AO9: SwM | AP9: VS | AQ9: DF
B10: PN | C10: Prasob Nambuthodiyil | D10: The Ninjas | E10: 1 | F10: =(1-(COUNTIF($AE$10:$AQ$23, $B10)/10))*$E10 -> 0.8 | G10: =(1-(COUNTIF($AE$24:$AQ$37, $B10)/10))*$E10 -> 1 | H10: =(1-(COUNTIF($AE$38:$AQ$51, $B10)/10))*$E10 -> 1 | I10: =(1-(COUNTIF($AE$52:$AQ$65, $B10)/10))*$E10 -> 1 | J10: =(1-(COUNTIF($AE$66:$AQ$79, $B10)/10))*$E10 -> 1 | K10: =(1-(COUNTIF($AE$80:$AQ$93, $B10)/10))*$E10 -> 1 | L10: =SUM(F10:K10)*8 -> 46.4 | M10: =SUM(F10:K10) *8 -> 46.4 | Q10: Apr | R10: 20 | AC10: AC
B11: SSRP | C11: Samba siva rao prudhivi | D11: The Ninjas | E11: 1 | F11: =(1-(COUNTIF($AE$10:$AQ$23, $B11)/10))*$E11 -> 0.9 | G11: =(1-(COUNTIF($AE$24:$AQ$37, $B11)/10))*$E11 -> 1 | H11: =(1-(COUNTIF($AE$38:$AQ$51, $B11)/10))*$E11 -> 1 | I11: =(1-(COUNTIF($AE$52:$AQ$65, $B11)/10))*$E11 -> 1 | J11: =(1-(COUNTIF($AE$66:$AQ$79, $B11)/10))*$E11 -> 1 | K11: =(1-(COUNTIF($AE$80:$AQ$93, $B11)/10))*$E11 -> 1 | L11: =SUM(F11:K11)*8 -> 47.2 | M11: =SUM(F11:K11) *8 -> 47.2 | R11: 21
B12: SS | C12: Shibu Swaminathan (repl) | D12: The Ninjas | E12: 1 | F12: =(1-(COUNTIF($AE$10:$AQ$23, $B12)/10))*$E12 -> 0.9 | G12: =(1-(COUNTIF($AE$24:$AQ$37, $B12)/10))*$E12 -> 1 | H12: =(1-(COUNTIF($AE$38:$AQ$51, $B12)/10))*$E12 -> 1 | I12: =(1-(COUNTIF($AE$52:$AQ$65, $B12)/10))*$E12 -> 1 | J12: =(1-(COUNTIF($AE$66:$AQ$79, $B12)/10))*$E12 -> 1 | K12: =(1-(COUNTIF($AE$80:$AQ$93, $B12)/10))*$E12 -> 1 | L12: =SUM(F12:K12)*8 -> 47.2 | M12: =SUM(F12:K12) *8 -> 47.2 | R12: 22 | AL12: PN
B13: SwM | C13: Swapna Madhu | D13: The Ninjas | E13: 1 | F13: =(1-(COUNTIF($AE$10:$AQ$23, $B13)/10))*$E13 -> 0.9 | G13: =(1-(COUNTIF($AE$24:$AQ$37, $B13)/10))*$E13 -> 1 | H13: =(1-(COUNTIF($AE$38:$AQ$51, $B13)/10))*$E13 -> 1 | I13: =(1-(COUNTIF($AE$52:$AQ$65, $B13)/10))*$E13 -> 1 | J13: =(1-(COUNTIF($AE$66:$AQ$79, $B13)/10))*$E13 -> 1 | K13: =(1-(COUNTIF($AE$80:$AQ$93, $B13)/10))*$E13 -> 1 | L13: =SUM(F13:K13)*8 -> 47.2 | M13: =SUM(F13:K13) *8 -> 47.2 | R13: 23
B14: VS | C14: Varun Sundar | D14: The Ninjas | E14: 0.2 | F14: =(1-(COUNTIF($AE$10:$AQ$23, $B14)/10))*$E14 -> 0.2 | G14: =(1-(COUNTIF($AE$24:$AQ$37, $B14)/10))*$E14 -> 0.2 | H14: =(1-(COUNTIF($AE$38:$AQ$51, $B14)/10))*$E14 -> 0.18 | I14: =(1-(COUNTIF($AE$52:$AQ$65, $B14)/10))*$E14 -> 0.2 | J14: =(1-(COUNTIF($AE$66:$AQ$79, $B14)/10))*$E14 -> 0.2 | K14: =(1-(COUNTIF($AE$80:$AQ$93, $B14)/10))*$E14 -> 0.18 | L14: =SUM(F14:K14)*8 -> 9.28 | M14: =SUM(F14:K14) *8 -> 9.28 | R14: 24
B15: DF | C15: Dana Fillhart | D15: The Ninjas | E15: 0.4 | F15: =(1-(COUNTIF($AE$10:$AQ$23, $B15)/10))*$E15 -> 0.4 | G15: =(1-(COUNTIF($AE$24:$AQ$37, $B15)/10))*$E15 -> 0.4 | H15: =(1-(COUNTIF($AE$38:$AQ$51, $B15)/10))*$E15 -> 0.36 | I15: =(1-(COUNTIF($AE$52:$AQ$65, $B15)/10))*$E15 -> 0.4 | J15: =(1-(COUNTIF($AE$66:$AQ$79, $B15)/10))*$E15 -> 0.28 | K15: =(1-(COUNTIF($AE$80:$AQ$93, $B15)/10))*$E15 -> 0.36 | L15: =SUM(F15:K15)*8 -> 17.6 | M15: =SUM(F15:K15) *8 -> 17.6 | R15: 25
A16: 12 | B16: AN | C16: Abdul Naik | D16: Samurai | E16: 1 | F16: =(1-(COUNTIF($S$10:$AD$23, $B16)/10))*$E16 -> 0.8 | G16: =(1-(COUNTIF($S$24:$AD$37, $B16)/10))*$E16 -> 0.7 | H16: =(1-(COUNTIF($S$38:$AD$51, $B16)/10))*$E16 -> 1 | I16: =(1-(COUNTIF($S$52:$AD$65, $B16)/10))*$E16 -> 1 | J16: =(1-(COUNTIF($S$66:$AD$79, $B16)/10))*$E16 -> 1 | K16: =(1-(COUNTIF($S$80:$AD$93, $B16)/10))*$E16 -> 1 | L16: =SUM(F16:K16)*8 -> 44 | M16: =SUM(F16:K16) *8 -> 44 | R16: 26 | Z16: RB
B17: AM | C17: Anoop Mohan | D17: Samurai | E17: 1 | F17: =(1-(COUNTIF($S$10:$AD$23, $B17)/10))*$E17 -> 0.8 | G17: =(1-(COUNTIF($S$24:$AD$37, $B17)/10))*$E17 -> 0.7 | H17: =(1-(COUNTIF($S$38:$AD$51, $B17)/10))*$E17 -> 1 | I17: =(1-(COUNTIF($S$52:$AD$65, $B17)/10))*$E17 -> 1 | J17: =(1-(COUNTIF($S$66:$AD$79, $B17)/10))*$E17 -> 1 | K17: =(1-(COUNTIF($S$80:$AD$93, $B17)/10))*$E17 -> 1 | L17: =SUM(F17:K17)*8 -> 44 | M17: =SUM(F17:K17) *8 -> 44 | R17: 27 | Z17: RB
B18: ASU | C18: Aravind Syama Unni | D18: Samurai | E18: 1 | F18: =(1-(COUNTIF($S$10:$AD$23, $B18)/10))*$E18 -> 0.9 | G18: =(1-(COUNTIF($S$24:$AD$37, $B18)/10))*$E18 -> 1 | H18: =(1-(COUNTIF($S$38:$AD$51, $B18)/10))*$E18 -> 1 | I18: =(1-(COUNTIF($S$52:$AD$65, $B18)/10))*$E18 -> 0.8 | J18: =(1-(COUNTIF($S$66:$AD$79, $B18)/10))*$E18 -> 1 | K18: =(1-(COUNTIF($S$80:$AD$93, $B18)/10))*$E18 -> 1 | L18: =SUM(F18:K18)*8 -> 45.6 | M18: =SUM(F18:K18) *8 -> 45.6 | R18: 28
B19: DF | C19: Dana Fillhart | D19: Samurai | E19: 0.6 | F19: =(1-(COUNTIF($S$10:$AD$23, $B19)/10))*$E19 -> 0.6 | G19: =(1-(COUNTIF($S$24:$AD$37, $B19)/10))*$E19 -> 0.6 | H19: =(1-(COUNTIF($S$38:$AD$51, $B19)/10))*$E19 -> 0.54 | I19: =(1-(COUNTIF($S$52:$AD$65, $B19)/10))*$E19 -> 0.6 | J19: =(1-(COUNTIF($S$66:$AD$79, $B19)/10))*$E19 -> 0.42 | K19: =(1-(COUNTIF($S$80:$AD$93, $B19)/10))*$E19 -> 0.54 | L19: =SUM(F19:K19)*8 -> 26.4 | M19: =SUM(F19:K19) *8 -> 26.4 | R19: 29 | AJ19: MM
B20: JR | C20: Johnson Robin | D20: Samurai | E20: 1 | F20: =(1-(COUNTIF($S$10:$AD$23, $B20)/10))*$E20 -> 0.8 | G20: =(1-(COUNTIF($S$24:$AD$37, $B20)/10))*$E20 -> 1 | H20: =(1-(COUNTIF($S$38:$AD$51, $B20)/10))*$E20 -> 1 | I20: =(1-(COUNTIF($S$52:$AD$65, $B20)/10))*$E20 -> 1 | J20: =(1-(COUNTIF($S$66:$AD$79, $B20)/10))*$E20 -> 1 | K20: =(1-(COUNTIF($S$80:$AD$93, $B20)/10))*$E20 -> 1 | L20: =SUM(F20:K20)*8 -> 46.4 | M20: =SUM(F20:K20) *8 -> 46.4 | AJ20: MM
B21: KN | C21: Krishnaraj Nagarajan | D21: Samurai | E21: 0.1 | F21: =(1-(COUNTIF($S$10:$AD$23, $B21)/10))*$E21 -> 0.1 | G21: =(1-(COUNTIF($S$24:$AD$37, $B21)/10))*$E21 -> 0.1 | H21: =(1-(COUNTIF($S$38:$AD$51, $B21)/10))*$E21 -> 0.09 | I21: =(1-(COUNTIF($S$52:$AD$65, $B21)/10))*$E21 -> 0.1 | J21: =(1-(COUNTIF($S$66:$AD$79, $B21)/10))*$E21 -> 0.1 | K21: =(1-(COUNTIF($S$80:$AD$93, $B21)/10))*$E21 -> 0.09 | L21: =SUM(F21:K21)*8 -> 4.64 | M21: =SUM(F21:K21) *8 -> 4.64
B22: MN | C22: Mala Nadar | D22: Samurai | E22: 1 | F22: =(1-(COUNTIF($S$10:$AD$23, $B22)/10))*$E22 -> 0.9 | G22: =(1-(COUNTIF($S$24:$AD$37, $B22)/10))*$E22 -> 1 | H22: =(1-(COUNTIF($S$38:$AD$51, $B22)/10))*$E22 -> 0.9 | I22: =(1-(COUNTIF($S$52:$AD$65, $B22)/10))*$E22 -> 0.7 | J22: =(1-(COUNTIF($S$66:$AD$79, $B22)/10))*$E22 -> 1 | K22: =(1-(COUNTIF($S$80:$AD$93, $B22)/10))*$E22 -> 1 | L22: =SUM(F22:K22)*8 -> 44 | M22: =SUM(F22:K22) *8 -> 44 | Q22: May | R22: 2 | S22: AN | T22: AM | U22: ASU | W22: JR | Z22: RB | AE22: AJ | AG22: KCK | AI22: LS | AJ22: MM | AK22: MHA | AL22: PN | AM22: SSRP | AN22: SS | AO22: SwM
B23: RB | C23: Rahul Bishnoi | D23: Samurai | E23: 1 | F23: =(1-(COUNTIF($S$10:$AD$23, $B23)/10))*$E23 -> 0.6 | G23: =(1-(COUNTIF($S$24:$AD$37, $B23)/10))*$E23 -> 1 | H23: =(1-(COUNTIF($S$38:$AD$51, $B23)/10))*$E23 -> 1 | I23: =(1-(COUNTIF($S$52:$AD$65, $B23)/10))*$E23 -> 1 | J23: =(1-(COUNTIF($S$66:$AD$79, $B23)/10))*$E23 -> 1 | K23: =(1-(COUNTIF($S$80:$AD$93, $B23)/10))*$E23 -> 1 | L23: =SUM(F23:K23)*8 -> 44.8 | M23: =SUM(F23:K23) *8 -> 44.8 | R23: 3 | S23: AN | T23: AM | W23: JR | Y23: MN | Z23: RB | AC23: AC | AD23: VA
B24: VS | C24: Varun Sundar | D24: Samurai | E24: 0.8 | F24: =(1-(COUNTIF($S$10:$AD$23, $B24)/10))*$E24 -> 0.8 | G24: =(1-(COUNTIF($S$24:$AD$37, $B24)/10))*$E24 -> 0.8 | H24: =(1-(COUNTIF($S$38:$AD$51, $B24)/10))*$E24 -> 0.72 | I24: =(1-(COUNTIF($S$52:$AD$65, $B24)/10))*$E24 -> 0.8 | J24: =(1-(COUNTIF($S$66:$AD$79, $B24)/10))*$E24 -> 0.8 | K24: =(1-(COUNTIF($S$80:$AD$93, $B24)/10))*$E24 -> 0.72 | L24: =SUM(F24:K24)*8 -> 37.12 | M24: =SUM(F24:K24) *8 -> 37.12 | Q24: May | R24: 4 | S24: AN | T24: AM
B25: VG | C25: Vilasini Ganesan | D25: Samurai | E25: 1 | F25: =(1-(COUNTIF($S$10:$AD$23, $B25)/10))*$E25 -> 1 | G25: =(1-(COUNTIF($S$24:$AD$37, $B25)/10))*$E25 -> 1 | H25: =(1-(COUNTIF($S$38:$AD$51, $B25)/10))*$E25 -> 0.9 | I25: =(1-(COUNTIF($S$52:$AD$65, $B25)/10))*$E25 -> 1 | J25: =(1-(COUNTIF($S$66:$AD$79, $B25)/10))*$E25 -> 1 | K25: =(1-(COUNTIF($S$80:$AD$93, $B25)/10))*$E25 -> 0.9 | L25: =SUM(F25:K25)*8 -> 46.4 | M25: =SUM(F25:K25) *8 -> 46.4 | R25: 5 | S25: AN | T25: AM
B26: AC | C26: Ashish Chourey | D26: Samurai | E26: 1 | F26: =(1-(COUNTIF($S$10:$AD$23, $B26)/10))*$E26 -> 0.8 | G26: =(1-(COUNTIF($S$24:$AD$37, $B26)/10))*$E26 -> 1 | H26: =(1-(COUNTIF($S$38:$AD$51, $B26)/10))*$E26 -> 1 | I26: =(1-(COUNTIF($S$52:$AD$65, $B26)/10))*$E26 -> 1 | J26: =(1-(COUNTIF($S$66:$AD$79, $B26)/10))*$E26 -> 1 | K26: =(1-(COUNTIF($S$80:$AD$93, $B26)/10))*$E26 -> 1 | L26: =SUM(F26:K26)*8 -> 46.4 | M26: =SUM(F26:K26) *8 -> 46.4 | R26: 6 | S26: AN | T26: AM
B27: VA | C27: Vijay Amirtharaj | D27: Samurai | E27: 1 | F27: =(1-(COUNTIF($S$10:$AD$23, $B27)/10))*$E27 -> 0.9 | G27: =(1-(COUNTIF($S$24:$AD$37, $B27)/10))*$E27 -> 1 | H27: =(1-(COUNTIF($S$38:$AD$51, $B27)/10))*$E27 -> 0.9 | I27: =(1-(COUNTIF($S$52:$AD$65, $B27)/10))*$E27 -> 0.7 | J27: =(1-(COUNTIF($S$66:$AD$79, $B27)/10))*$E27 -> 1 | K27: =(1-(COUNTIF($S$80:$AD$93, $B27)/10))*$E27 -> 1 | L27: =SUM(F27:K27)*8 -> 44 | M27: =SUM(F27:K27) *8 -> 44
K29: what does 1,2,3,5 SP mean? | R29: 9
K30: 1- 1-10 | R30: 10 | AJ30: MM
K31: 2 -10-30 | R31: 11
K32: 3 -30-50 | R32: 12
K33: 5 - 50-70 | R33: 13
K34: 8- >70 | O34: =K35*L35*M35 -> 672
K35: 9.6 | L35: 7 | M35: 10
R36: 16
R37: 17
Q38: May | R38: 18
M39: =4.8*8 -> 38.4 | R39: 19
R40: 20 | AD40: VA
R43: 23 | AE43: AJ
...

Sheet ResourceAllocationByPriority
A1: Core | I1: PI-8 Samurai Work Items - Boards (azure.com)
I2: Resource | J2: Story points total till 7/12 | L2: Product description | M2: Product Release | N2: Priority # | P2: Samurai Resource | Q2: Available Hours: Pulled from Resource Planning till 7/12 DO NOT EDIT
D3: NinJa Sprint | E3: Sprint DevOps | F3: Sprint PI | I3: Abhijith Jayakumar | J3: =VLOOKUP($I3, 'Resource Planning'!$C$3:$M$13, 11, FALSE) -> 46.4 | P3: Abdul Naik | Q3: =VLOOKUP($P3, 'Resource Planning'!$C$16:$M$27, 11, FALSE) -> 44
D4: 59 | E4: 98 | F4: 1 | I4: Jagadeesan Balasubramanian | J4: =VLOOKUP($I4, 'Resource Planning'!$C$3:$M$13, 11, FALSE) -> 46.4 | L4: BAU | M4: PROOF | N4: 1 | P4: Anoop Mohan | Q4: =VLOOKUP($P4, 'Resource Planning'!$C$16:$M$27, 11, FALSE) -> 44
D5: 60 | E5: 99 | F5: 2 | I5: Krishna chandar kandula | J5: =VLOOKUP($I5, 'Resource Planning'!$C$3:$M$13, 11, FALSE) -> 47.2 | L5: BAU | M5: GRID | N5: 1 | P5: Aravind Syama Unni | Q5: =VLOOKUP($P5, 'Resource Planning'!$C$16:$M$27, 11, FALSE) -> 45.6
D6: 61 | E6: 100 | F6: 3 | I6: Krishnaraj Nagaraj | J6: =VLOOKUP($I6, 'Resource Planning'!$C$3:$M$13, 11, FALSE) -> 43.2 | L6: BAU | M6: DOS | N6: 1 | P6: Dana Fillhart | Q6: =VLOOKUP($P6, 'Resource Planning'!$C$16:$M$27, 11, FALSE) -> 26.4
D7: 62 | E7: 101 | F7: 4 | I7: Lokeshwaran Sankar | J7: =VLOOKUP($I7, 'Resource Planning'!$C$3:$M$13, 11, FALSE) -> 47.2 | L7: BAU | M7: IDC | N7: 1 | P7: Johnson Robin | Q7: =VLOOKUP($P7, 'Resource Planning'!$C$16:$M$27, 11, FALSE) -> 46.4
D8: 63 | E8: 102 | F8: 5 | I8: Manoj Madhavan | J8: =VLOOKUP($I8, 'Resource Planning'!$C$3:$M$13, 11, FALSE) -> 44 | M8: ADJ | N8: 1 | P8: Krishnaraj Nagarajan | Q8: =VLOOKUP($P8, 'Resource Planning'!$C$16:$M$27, 11, FALSE) -> 4.64
D9: 64 | E9: 103 | F9: 6 | I9: Meraj Husen Ansari | J9: =VLOOKUP($I9, 'Resource Planning'!$C$3:$M$13, 11, FALSE) -> 47.2 | M9: Databricks Optimization | N9: 2 | P9: Mala Nadar | Q9: =VLOOKUP($P9, 'Resource Planning'!$C$16:$M$27, 11, FALSE) -> 44
I10: Prasob Nambuthodiyil | J10: =VLOOKUP($I10, 'Resource Planning'!$C$3:$M$13, 11, FALSE) -> 46.4 | M10: IDC2 | N10: 2.1 | P10: Rahul Bishnoi | Q10: =VLOOKUP($P10, 'Resource Planning'!$C$16:$M$27, 11, FALSE) -> 44.8
I11: Samba siva rao prudhivi | J11: =VLOOKUP($I11, 'Resource Planning'!$C$3:$M$13, 11, FALSE) -> 47.2 | M11: GDV | N11: 2.1 | P11: Varun Sundar | Q11: =VLOOKUP($P11, 'Resource Planning'!$C$16:$M$27, 11, FALSE) -> 37.12
I12: Shibu Swaminathan (repl) | J12: =VLOOKUP($I12, 'Resource Planning'!$C$3:$M$13, 11, FALSE) -> 47.2 | M12: DOS RESI | N12: 2.1 | P12: Vilasini Ganesan | Q12: =VLOOKUP($P12, 'Resource Planning'!$C$16:$M$27, 11, FALSE) -> 46.4
I13: Swapna Madhu (Bishva) | J13: =VLOOKUP($I13, 'Resource Planning'!$C$3:$M$13, 11, FALSE) -> #N/A | M13: DOS QA Automation | N13: 2.3 | P13: Ashish Chourey | Q13: =VLOOKUP($P13, 'Resource Planning'!$C$16:$M$27, 11, FALSE) -> 46.4
M14: GRID QA Automation | N14: 2.3 | P14: Vijay Amirtharaj | Q14: =VLOOKUP($P14, 'Resource Planning'!$C$16:$M$27, 11, FALSE) -> 44
M15: Rewiring | N15: 3 | P15: UNASSIGNED | Q15: =VLOOKUP($P15, 'Resource Planning'!$C$16:$M$27, 11, FALSE) -> #N/A
M16: Historical Load | N16: 3.1
M17: Future State Data project | N17: 3.2
M18: Release on Demand | N18: 3.3
M19: DOS RE Equity | N19: 3.4
B21: Combined Available story points total till 4/15 | C21: Actual story points total til 4/15
B22: Resource | C22: (Pulled from the Resource Planning tab - DO NOT EDIT) | D22: GDV | E22: GRID | F22: GRIDAdjustments | G22: GRIDTestAutomation | H22: IDC | I22: IDC2 | J22: Rewiring | K22: DOS BAU | L22: MIS Refactoring | M22: ResidentialLoans | N22: DatabricksPlatformOptimization | O22: IDC Rewiring | P22: RE Equity | Q22: Release-on-Demand | R22: TechDebt | S22: Untagged
B23: Abdul Naik | C23: =VLOOKUP($B23, 'Resource Planning'!$C$16:$M$27, 11, FALSE) -> 44
B24: Anoop Mohan | C24: =VLOOKUP($B24, 'Resource Planning'!$C$16:$M$27, 11, FALSE) -> 44
B25: Aravind Syama Unni | C25: =VLOOKUP($B25, 'Resource Planning'!$C$16:$M$27, 11, FALSE) -> 45.6
B26: Dana Fillhart | C26: =VLOOKUP($B26, 'Resource Planning'!$C$16:$M$27, 11, FALSE) -> 26.4
B27: Johnson Robin | C27: =VLOOKUP($B27, 'Resource Planning'!$C$16:$M$27, 11, FALSE) -> 46.4
B28: Krishnaraj Nagarajan | C28: =VLOOKUP($B28, 'Resource Planning'!$C$16:$M$27, 11, FALSE) -> 4.64
B29: Mala Nadar | C29: =VLOOKUP($B29, 'Resource Planning'!$C$16:$M$27, 11, FALSE) -> 44
B30: Rahul Bishnoi | C30: =VLOOKUP($B30, 'Resource Planning'!$C$16:$M$27, 11, FALSE) -> 44.8
B31: Varun Sundar | C31: =VLOOKUP($B31, 'Resource Planning'!$C$16:$M$27, 11, FALSE) -> 37.12
B32: Vilasini Ganesan | C32: =VLOOKUP($B32, 'Resource Planning'!$C$16:$M$27, 11, FALSE) -> 46.4
B33: Ashish Chourey | C33: =VLOOKUP($B33, 'Resource Planning'!$C$16:$M$27, 11, FALSE) -> 46.4
B34: Vijay Amirtharaj | C34: =VLOOKUP($B34, 'Resource Planning'!$C$16:$M$27, 11, FALSE) -> 44
B35: UNASSIGNED | C35: =VLOOKUP($B35, 'Resource Planning'!$C$16:$M$27, 11, FALSE) -> #N/A
AU36: 93,94,95
AU37: lot of work tracking
K38: Tags (Column M) | AU38: Core Data Services
P39: Vilasini/Krishnaraj/Dana to discuss for IDC 2 | S39: (need placeholders for rewiring and GDV) | AU39: Core Data Services\Cloud Services
P40: Core Data Services\Cloud Services | S40: 93,94,95 | W40: 95 | AI40: Krishnaraj to talk to Varun for IDC2 API stories
C41: 0.7 | D41: IDC2 | E41: 93,94 | G41: 0.35 | H41: IDC2 | L41: 93,94 | O41: IDC2 | P41: 0.4 | S41: Core Data Services\Cloud Services | W41: 5% for calls and IDC | AA41: 93,94,95,97 | AE41: 93,94,97 | AI41: 93 | AM41: 93,94,95,97 | AR41: 65 story points | AU41: 154 SP | AY41: 54 Unassigned points
...

Sheet Sheet2
E1: Samurais: Proportional Available Hours - Sprints 1-6 | F1: Samurais - Proportional Actual hours - Sprints 1-6 | G1: Difference | M1: Resource | N1: Product Releasae | O1: % | P1: Story points Total Available | Q1: Story points ask upto 4/15 | R1: Prasob update points in this column if changes are needed in F
A2: Core Data Services | B2: Abdul Naik | C2: GRID / GRID Adj. | D2: 0 | E2: =VLOOKUP($B$2, ResourceAllocationByPriority!$B$23:$C34, 2, FALSE)*$D2 -> 0 | F2: {=SUMPRODUCT(--(ResourceAllocationByPriority!$B$23:$B$34=$B$2), ResourceAllocationByPriority!$D$23:$D$34)} -> 0 | G2: =$E2-$F2 -> 0 | L2: Shared Services | M2: Abhijith | N2: PROOF BAU | O2: 0.5 | P2: =ResourceAllocationByPriority!$J$3*O2 -> 23.2 | Q2: 30 | R2: =P2-Q2 -> -6.8
C3: IDC | D3: 0.5 | E3: =VLOOKUP($B$2, ResourceAllocationByPriority!$B$23:$C35, 2, FALSE)*$D3 -> 22 | F3: {=SUMPRODUCT(--(ResourceAllocationByPriority!$B$23:$B$34=$B$2), ResourceAllocationByPriority!$E$23:$E$34)} -> 0 | G3: =$E3-$F3 -> 22 | M3: Abhijith | N3: Adj | O3: 0.4 | P3: =ResourceAllocationByPriority!$J$3*O3 -> 18.56 | Q3: 1 | R3: =P3-Q3 -> 17.56
C4: IDC2 | D4: 0.25 | E4: =VLOOKUP($B$2, ResourceAllocationByPriority!$I$23:$J36, 2, FALSE)*$D4 -> #N/A | F4: {=SUMPRODUCT(--(ResourceAllocationByPriority!$B$23:$B$34=$B$2), ResourceAllocationByPriority!$F$23:$F$34)} -> 0 | G4: =$E4-$F4 -> #N/A | M4: Abhijith | N4: IDC | O4: 0.1 | P4: =ResourceAllocationByPriority!$J$3*O4 -> 4.64 | Q4: 7 | R4: =P4-Q4 -> -2.36
C5: DOS | D5: 0.25 | E5: =VLOOKUP($B$2, ResourceAllocationByPriority!$I$23:$J37, 2, FALSE)*$D5 -> #N/A | F5: {=SUMPRODUCT(--(ResourceAllocationByPriority!$B$23:$B$34=$B$2), ResourceAllocationByPriority!$D$23:$D$34)} -> 0 | G5: =$E5-$F5 -> #N/A | M5: Abhijith | N5: IDC2 | O5: 0 | P5: =ResourceAllocationByPriority!$J$3*O5 -> 0 | R5: =P5-Q5 -> 0
B6: Anoop Mohan | C6: GRID / GRID Adj. | D6: 0.2 | E6: =VLOOKUP($B$6, ResourceAllocationByPriority!$B$23:$C$34, 2, FALSE)*$D6 -> 8.8 | F6: {=SUMPRODUCT(--(ResourceAllocationByPriority!$B$23:$B$34=$B6), ResourceAllocationByPriority!$D$23:$D$34)} -> 0 | G6: =$E6-$F6 -> 8.8 | M6: Prasob | N6: PROOF | O6: 0.4 | P6: =ResourceAllocationByPriority!$J$4*O6 -> 18.56 | Q6: 7 | R6: =P6-Q6 -> 11.56
C7: IDC | D7: 0.5 | E7: =VLOOKUP($B$6, ResourceAllocationByPriority!$B$23:$C$34, 2, FALSE)*$D7 -> 22 | F7: =VLOOKUP($B$6, ResourceAllocationByPriority!$B$22:$K$34, 4, FALSE) -> 0 | G7: =$E7-$F7 -> 22 | M7: Prasob | N7: IDC2 | O7: 0.6 | P7: =ResourceAllocationByPriority!$J$4*O7 -> 27.84 | Q7: 32 | R7: =P7-Q7 -> -4.16
C8: IDC2 | D8: 0.2 | E8: =VLOOKUP($B$6, ResourceAllocationByPriority!$B$23:$C$34, 2, FALSE)*$D8 -> 8.8 | F8: =VLOOKUP($B$6, ResourceAllocationByPriority!$B$22:$K$34, 5, FALSE) -> 0 | G8: =$E8-$F8 -> 8.8 | M8: Manoj | N8: Adj | O8: 0.8 | P8: =ResourceAllocationByPriority!$J$5*O8 -> 37.76 | Q8: 15 | R8: =P8-Q8 -> 22.76
C9: DOS | D9: 0.1 | E9: =VLOOKUP($B$6, ResourceAllocationByPriority!$B$23:$C$34, 2, FALSE)*$D9 -> 4.4 | F9: =VLOOKUP($B$6, ResourceAllocationByPriority!$B$22:$K$34, 6, FALSE) -> 0 | G9: =$E9-$F9 -> 4.4 | M9: Manoj | N9: IDC2 | O9: 0.2 | P9: =ResourceAllocationByPriority!$J$5*O9 -> 9.44 | Q9: 5 | R9: =P9-Q9 -> 4.44
B10: Aravind Syama Unni | C10: GRID / GRID Adj. | D10: 0 | E10: =VLOOKUP($B$10, ResourceAllocationByPriority!$I$22:$J38, 2, FALSE)*$D10 -> #N/A | F10: =VLOOKUP($B$10, ResourceAllocationByPriority!$B$22:$K$34, 3, FALSE) -> 0 | G10: =$E10-$F10 -> #N/A | M10: Manoj | N10: PROOF | O10: 0.8 | P10: =ResourceAllocationByPriority!$J$5*O10 -> 37.76 | Q10: 10 | R10: =P10-Q10 -> 27.76
C11: IDC | D11: 0.5 | E11: =VLOOKUP($B$10, ResourceAllocationByPriority!$I$22:$J38, 2, FALSE)*$D11 -> #N/A | F11: =VLOOKUP($B$10, ResourceAllocationByPriority!$B$22:$K$34, 4, FALSE) -> 0 | G11: =$E11-$F11 -> #N/A | M11: Krishna | N11: ADJ | O11: 0.2 | P11: =ResourceAllocationByPriority!$J$5*O11 -> 9.44 | Q11: 3 | R11: =P11-Q11 -> 6.44
C12: IDC2 | D12: 0 | E12: =VLOOKUP($B$10, ResourceAllocationByPriority!$I$22:$J38, 2, FALSE)*$D12 -> #N/A | F12: =VLOOKUP($B$10, ResourceAllocationByPriority!$B$22:$K$34, 5, FALSE) -> 0 | G12: =$E12-$F12 -> #N/A | M12: Krishna | N12: IDC-2 | O12: 0.8 | P12: =ResourceAllocationByPriority!$J$5*O12 -> 37.76 | Q12: 36 | R12: =P12-Q12 -> 1.76
C13: DOS | D13: 0.5 | E13: =VLOOKUP($B$10, ResourceAllocationByPriority!$I$22:$J38, 2, FALSE)*$D13 -> #N/A | F13: =VLOOKUP($B$10, ResourceAllocationByPriority!$B$22:$K$34, 6, FALSE) -> 0 | G13: =$E13-$F13 -> #N/A | M13: Samba | N13: ADJ | O13: 1 | P13: =ResourceAllocationByPriority!$J$5*O13 -> 47.2 | Q13: 17 | R13: =P13-Q13 -> 30.2
B14: Dana Fillhart | C14: GRID / GRID Adj. | D14: 0.1 | E14: =VLOOKUP($B$14, ResourceAllocationByPriority!$I$22:$J38, 2, FALSE)*$D14 -> #N/A | F14: =VLOOKUP($B$14, ResourceAllocationByPriority!$B$22:$K$34, 3, FALSE) -> 0 | G14: =$E14-$F14 -> #N/A | M14: Swapna | N14: IDC | O14: 0.3 | P14: =ResourceAllocationByPriority!$J$5*O14 -> 14.16 | Q14: 16 | R14: =P14-Q14 -> -1.84
C15: IDC | D15: 0 | E15: =VLOOKUP($B$14, ResourceAllocationByPriority!$I$22:$J38, 2, FALSE)*$D15 -> #N/A | F15: =VLOOKUP($B$14, ResourceAllocationByPriority!$B$22:$K$34, 4, FALSE) -> 0 | G15: =$E15-$F15 -> #N/A | M15: Swapna | N15: IDC-2 | O15: 0.2 | P15: =ResourceAllocationByPriority!$J$5*O15 -> 9.44 | Q15: 10 | R15: =P15-Q15 -> -0.56
C16: IDC2 | D16: 0 | E16: =VLOOKUP($B$14, ResourceAllocationByPriority!$I$22:$J38, 2, FALSE)*$D16 -> #N/A | F16: =VLOOKUP($B$14, ResourceAllocationByPriority!$B$22:$K$34, 5, FALSE) -> 0 | G16: =$E16-$F16 -> #N/A | M16: Swapna | N16: PROOF | O16: 0.5 | P16: =ResourceAllocationByPriority!$J$5*O16 -> 23.6 | Q16: 16 | R16: =P16-Q16 -> 7.6
C17: DOS | D17: 0.9 | E17: =VLOOKUP($B$14, ResourceAllocationByPriority!$I$22:$J38, 2, FALSE)*$D17 -> #N/A | F17: =VLOOKUP($B$14, ResourceAllocationByPriority!$B$22:$K$34,6, FALSE) -> 0 | G17: =$E17-$F17 -> #N/A | M17: Shiju | N17: PROOF BAU | O17: 0.2 | P17: =ResourceAllocationByPriority!$J$5*O17 -> 9.44 | Q17: 6 | R17: =P17-Q17 -> 3.44
B18: Johnson Robin | C18: GRID / GRID Adj. | D18: 0.25 | E18: =VLOOKUP($B$18, ResourceAllocationByPriority!$I$22:$J38, 2, FALSE)*$D18 -> #N/A | F18: =VLOOKUP($B$18, ResourceAllocationByPriority!$B$22:$K$34, 3, FALSE) -> 0 | G18: =$E18-$F18 -> #N/A | M18: Shiju | N18: IDC-2 | O18: 0.8 | P18: =ResourceAllocationByPriority!$J$5*O18 -> 37.76 | Q18: 30 | R18: =P18-Q18 -> 7.76
C19: IDC | D19: 0.25 | E19: =VLOOKUP($B$18, ResourceAllocationByPriority!$I$22:$J38, 2, FALSE)*$D19 -> #N/A | F19: =VLOOKUP($B$18, ResourceAllocationByPriority!$B$22:$K$34,4, FALSE) -> 0 | G19: =$E19-$F19 -> #N/A | M19: Jagan | N19: iRIDER | O19: 0.2 | P19: =ResourceAllocationByPriority!$J$5*O19 -> 9.44 | Q19: 4 | R19: =P19-Q19 -> 5.44
C20: IDC 2 | D20: 0 | E20: =VLOOKUP($B$18, ResourceAllocationByPriority!$I$22:$J38, 2, FALSE)*$D20 -> #N/A | F20: =VLOOKUP($B$18, ResourceAllocationByPriority!$B$22:$K$34,5, FALSE) -> 0 | G20: =$E20-$F20 -> #N/A | M20: Jagan | N20: PROOF | O20: 0.8 | P20: =ResourceAllocationByPriority!$J$5*O20 -> 37.76 | Q20: 33 | R20: =P20-Q20 -> 4.76
C21: DOS | D21: 0.5 | E21: =VLOOKUP($B$18, ResourceAllocationByPriority!$I$22:$J38, 2, FALSE)*$D21 -> #N/A | F21: =VLOOKUP($B$18, ResourceAllocationByPriority!$B$22:$K$34, 6, FALSE) -> 0 | G21: =$E21-$F21 -> #N/A | M21: Krishnaraj | N21: IDC-2 | O21: 0.7 | P21: =ResourceAllocationByPriority!$J$5*O21 -> 33.04 | Q21: 20 | R21: =P21-Q21 -> 13.04
B22: Krishnaraj Nagarajan | C22: GRID / GRID Adj. | D22: 0.5 | E22: =ResourceAllocationByPriority!$C$26*D22 -> 13.2 | F22: =VLOOKUP($B$22, ResourceAllocationByPriority!$B$22:$K$34, 3, FALSE) -> 0 | G22: =$E22-$F22 -> 13.2 | M22: Meraj | N22: IDC | O22: 0.4 | P22: =ResourceAllocationByPriority!$J$5*O22 -> 18.88 | Q22: 13 | R22: =P22-Q22 -> 5.88
C23: IDC | D23: 0 | E23: =ResourceAllocationByPriority!$C$26*D23 -> 0 | F23: =VLOOKUP($B$22, ResourceAllocationByPriority!$B$22:$K$34, 4, FALSE) -> 0 | G23: =$E23-$F23 -> 0 | M23: Meraj | N23: IDC-2 | O23: 0.2 | P23: =ResourceAllocationByPriority!$J$5*O23 -> 9.44 | Q23: 9 | R23: =P23-Q23 -> 0.44
C24: IDC 2 | D24: 0.5 | E24: =ResourceAllocationByPriority!$C$26*D24 -> 13.2 | F24: =VLOOKUP($B$22, ResourceAllocationByPriority!$B$22:$K$34,5, FALSE) -> 0 | G24: =$E24-$F24 -> 13.2 | M24: Meraj | N24: PROOF | O24: 0.4 | P24: =ResourceAllocationByPriority!$J$5*O24 -> 18.88 | Q24: 15 | R24: =P24-Q24 -> 3.88
C25: DOS | D25: 0 | E25: =ResourceAllocationByPriority!$C$26*D25 -> 0 | F25: =VLOOKUP($B$22, ResourceAllocationByPriority!$B$22:$K$34, 6, FALSE) -> 0 | G25: =$E25-$F25 -> 0
B26: Mala Nadar | C26: GRID | D26: 0 | E26: =ResourceAllocationByPriority!$C$26*D26 -> 0 | F26: =VLOOKUP($B$26, ResourceAllocationByPriority!$B$22:$K$34, 3, FALSE) -> 0 | G26: =$E26-$F26 -> 0
C27: IDC | D27: 0.5 | E27: =ResourceAllocationByPriority!$C$26*D27 -> 13.2 | F27: =VLOOKUP($B$26, ResourceAllocationByPriority!$B$22:$K$34, 4, FALSE) -> 0 | G27: =$E27-$F27 -> 13.2
C28: IDC2 | D28: 0 | E28: =ResourceAllocationByPriority!$C$26*D28 -> 0 | F28: =VLOOKUP($B$26, ResourceAllocationByPriority!$B$22:$K$34, 5, FALSE) -> 0 | G28: =$E28-$F28 -> 0
C29: DOS | D29: 0.5 | E29: =ResourceAllocationByPriority!$C$26*D29 -> 13.2 | F29: =VLOOKUP($B$26, ResourceAllocationByPriority!$B$22:$K$34,6, FALSE) -> 0 | G29: =$E29-$F29 -> 13.2
B30: Rahul Bishnoi | C30: GRID | D30: 0.25 | E30: =ResourceAllocationByPriority!$C$26*D30 -> 6.6 | F30: =VLOOKUP($B$30, ResourceAllocationByPriority!$B$22:$K$34, 3, FALSE) -> 0 | G30: =$E30-$F30 -> 6.6
C31: IDC | D31: 0.5 | E31: =ResourceAllocationByPriority!$C$26*D31 -> 13.2 | F31: =VLOOKUP($B$30, ResourceAllocationByPriority!$B$22:$K$34, 4, FALSE) -> 0 | G31: =$E31-$F31 -> 13.2
C32: IDC 2 | D32: 0 | E32: =ResourceAllocationByPriority!$C$26*D32 -> 0 | F32: =VLOOKUP($B$30, ResourceAllocationByPriority!$B$22:$K$34, 5, FALSE) -> 0 | G32: =$E32-$F32 -> 0
C33: DOS | D33: 0.25 | E33: =ResourceAllocationByPriority!$C$26*D33 -> 6.6 | F33: =VLOOKUP($B$30, ResourceAllocationByPriority!$B$22:$K$34, 6, FALSE) -> 0 | G33: =$E33-$F33 -> 6.6
B34: Varun Sundar | C34: GRID | D34: 0 | E34: =ResourceAllocationByPriority!$C$26*D34 -> 0 | F34: =VLOOKUP($B$34, ResourceAllocationByPriority!$B$22:$K$34, 3, FALSE) -> 0 | G34: =$E34-$F34 -> 0
C35: IDC | D35: 0.2 | E35: =ResourceAllocationByPriority!$C$26*D35 -> 5.28 | F35: =VLOOKUP($B$34, ResourceAllocationByPriority!$B$22:$K$34, 4, FALSE) -> 0 | G35: =$E35-$F35 -> 5.28
C36: IDC 2 | D36: 0 | E36: =ResourceAllocationByPriority!$C$26*D36 -> 0 | F36: =VLOOKUP($B$34, ResourceAllocationByPriority!$B$22:$K$34, 5, FALSE) -> 0 | G36: =$E36-$F36 -> 0
C37: DOS | D37: 0.8 | E37: =ResourceAllocationByPriority!$C$26*D37 -> 21.12 | F37: =VLOOKUP($B$34, ResourceAllocationByPriority!$B$22:$K$34, 6, FALSE) -> 0 | G37: =$E37-$F37 -> 21.12
B38: Vilasini Ganesan | C38: GRID | D38: 0.5 | E38: =ResourceAllocationByPriority!$C$26*D38 -> 13.2 | F38: =VLOOKUP($B$38, ResourceAllocationByPriority!$B$22:$K$34, 3, FALSE) -> 0 | G38: =$E38-$F38 -> 13.2
C39: IDC | D39: 0.4 | E39: =ResourceAllocationByPriority!$C$26*D39 -> 10.56 | F39: =VLOOKUP($B$38, ResourceAllocationByPriority!$B$22:$K$34, 4, FALSE) -> 0 | G39: =$E39-$F39 -> 10.56
C40: IDC 2 | D40: 0 | E40: =ResourceAllocationByPriority!$C$26*D40 -> 0 | F40: =VLOOKUP($B$38, ResourceAllocationByPriority!$B$22:$K$34, 5, FALSE) -> 0 | G40: =$E40-$F40 -> 0
...

Sheet HistorySP
D1: DOS | E1: GRID | K1: The Ninjas
C2: Sprint | D2: Delivered Story Points | E2: Delivered Story Points | F2: Total Story Points | L2: Sprint | N2: velocity | O2: capacity in hrs
C3: 74 | D3: 70 | E3: 51 | F3: =SUM(D3:E3) -> 121 | L3: 39 | O3: 445
C4: 75 | D4: 102 | E4: 66 | F4: =SUM(D4:E4) -> 168 | L4: 40
C5: 76 | D5: 150 | E5: 68 | F5: =SUM(D5:E5) -> 218 | L5: 41
C6: 77 | D6: 148 | E6: 88 | F6: =SUM(D6:E6) -> 236 | K6: PI6 | L6: 42 | N6: 67 | O6: 480
C7: 78 | D7: 104 | E7: 105 | F7: =SUM(D7:E7) -> 209 | L7: 43 | N7: 56 | O7: 480
C8: 79 | D8: 134 | E8: 84 | F8: =SUM(D8:E8) -> 218 | L8: 44 | N8: 57 | O8: 480 | S8: Resource | T8: Avg Story points per resource
C9: 80 | D9: 136 | E9: =61+27 -> 88 | F9: =SUM(D9:E9) -> 224 | L9: 45 | N9: 60 | O9: 480 | R9: =AVERAGE(N3:N8) -> 60 | S9: 8 | T9: =R9/S9 -> 7.5
L10: 46 | N10: 54 | O10: 480
F11: Resource | G11: Avg Story points per resource | L11: 47 | N11: 57 | O11: 480
E12: =AVERAGE(F3:F9) -> 199.14286 | F12: 9 | G12: =E12/F12 -> 22.126984 | K12: PI7 | L12: 48 | N12: 75 | O12: 680
L13: 49 | N13: 74 | O13: 666
E14: Considering holidays, timeoff, team story point capacity/sprint: | F14: 185 | L14: 50 | N14: 73 | O14: 617
L15: 51 | N15: 76 | O15: 638 | S15: Resource | T15: Avg Story points per resource
L16: 52 | N16: 75 | O16: 680 | R16: =AVERAGE(N12:N16) -> 74.6 | S16: 10 | T16: =R16/S16 -> 7.46
E17: GRID Allocation | F17: 120
E18: DOS Allocation | F18: 65 | K18: PI 8 | L18: 53 | O18: 796
L19: 54 | O19: 789
L20: 55 | O20: 810
L21: 56 | O21: 810
L22: 57 | O22: 782
L23: 58 | O23: 810

Sheet ProgramPriorityFeatures
B1: From Brian
B2: 1 | C2: Testing and Deploying Master Data Synch
B3: 2 | C3: Complete changes for Privates Placement Multi-Currency
B4: 3 | C4: Complete UI and begin IT testing for Private Structured Credit
B5: 4 | C5: Entitlement enhancements for Data and Documents separation
B6: 5 | C6: Development for Residential Loans
B7: 6 | C7: Implement Document Streaming
B8: 7 | C8: Automate MIM Relationship Portal contacts
B9: 8 | C9: Screen design for RE Equity (No Development)
A14: SAMURAI | D14: 6 sprints
C15: GRID IDC - BAU 2022.05 Release (May 2022) | D15: 8
C16: GRID IDC - BAU 2022.06 Release (June 2022) | D16: 8
C17: GRID IDC - BAU 2022.07 Release (July 2022) | D17: 8
C18: GRID IDC - BAU 2022.08 Release (August 2022) | D18: 5
C19: GRID - BAU 2022.05 Release (May 2022) | D19: 8
C20: GRID - BAU 2022.06 Release (June 2022) | D20: 8
C21: GRID - BAU 2022.07 Release (July 2022) | D21: 8
C22: GRID - BAU 2022.08 Release (August 2022) | D22: 5
B23: Feature | C23: GRID Automated Data Validations - May 2022 | D23: 35
C24: GRID Automated Data Validations - June 2022 | D24: 15 | P24: story | Q24: DOS - BAU 2022.05 Release (May 2022) - COML
C25: GRID Automated Data Validations - July 2022 | D25: 15 | P25: Task | Q25: Task1
C26: GRID Automated Data Validations - August 2022 | D26: 5 | P26: Task | Q26: Task2
C27: GRID QA Automation | D27: 15 | Q27: DOS - BAU 2022.05 Release (May 2022) - AGRI
C28: GRID: Reserve capacity for Next PI Planning, System Demo and Innovation | D28: 8 | Q28: DOS - BAU 2022.05 Release (May 2022) - Privates/PABS
C29: GRID/IDC Rewiring | D29: 15 | Q29: DOS - BAU 2022.05 Release (May 2022) - SIT
C30: GRID REI Historical Load | D30: 8 | Q30: DOS - BAU 2022.05 Release (May 2022) - UAT
C31: GRID/DOS/GRID Adj AM KT | D31: 8
C32: GRID IDC AllVue | D32: 10
C33: GRID ESG Star | D33: 3
C34: GRID-Future State Data Project | D34: 55
C35: GRID - IDC Data Project - Client Reporting | D35: 15
C36: DOS - BAU 2022.05 Release (May 2022) | D36: 15
C37: DOS - BAU 2022.06 Release (June 2022) | D37: 20
C38: DOS - BAU 2022.07 Release (July 2022) | D38: 20
C39: DOS - BAU 2022.08 Release (August 2022) | D39: 20
C40: DOS Databricks Optimization | D40: 8
C41: DOS Residential | D41: 8
C42: DOS RE Equity | D42: 8
... C44: DOS Release On Demand | D44: 8
B45: Future State data project | C45: DOS: Reserve capacity for Next PI Planning, System Demo and Innovation | D45: 8
...

Sheet PI Commitments
G1: manual | H1: manual | I1: (auto populate) | J1: manual ( H= J for beginning). Periodically(SOS) manually reduce | K1: auto | L1: manual | Q1: manual | R1: manual | S1: auto | T1: auto (equally distributing) | Z1: manual | AA1: manual | AB1: manual | AC1: << not being used>> | AD1: << not being used>>
B2: ID | C2: Title | D2: Work Item Type | E2: Assigned To | F2: WSJF | G2: Business Value | H2: Effort | I2: Size | J2: Rem Effort | K2: Remaining Size | L2: Target Date | M2: State | N2: Commit | O2: Category | P2: Team | Q2: Start in | R2: Deliver in | S2: Duration | T2: S1 | U2: S2 | V2: S3 | W2: S4 | X2: S5 | Y2: s6 | Z2: INT | AA2: QA | AB2: Prod | AC2: % Complete | AD2: Actual Business Value
C3: GRID IDC - BAU 2022.05 Release (May 2022) | G3: 8 | H3: 1.6 | I3: =VLOOKUP(H3,$AF$3:$AG$156,2,FALSE) -> 8 | J3: 1.6 | K3: =IF(J3 > 0, VLOOKUP(J3,$AF$3:$AG$103,2,FALSE),0) -> 8 | M3: New | N3: Commit | O3: BAU | P3: S | Q3: 1 | R3: 2 | S3: =(R3+1) - 1 -> 2 | T3: =IF(AND(R3>=1, $A$1 <=1,Q3<=1), (K3/ ((R3 +1) - 1))*(Team!$H$25/10), 0) -> 4 | U3: =IF(AND(R3>=2, $A$1 <=2, Q3<=2), ((K3-T3)/ ((R3 +1) - 2))*(Team!$H$26/10), 0) -> 4 | V3: =IF(AND(R3>=3, $A$1 <=3, Q3<=3), ((K3-(T3+U3))/ ((R3 +1) - 3))*(Team!$H$27/10), 0) -> 0 | W3: =IF(AND(R3>=4, $A$1 <=4, Q3<=4), ((K3-(T3+U3+V3))/ ((R3 +1) - 4))*(Team!$H$28/10), 0) -> 0 | X3: =IF(AND(R3>=5, $A$1 <5, Q3<=5), ((K3-(T3+U3+V3+W3))/ ((R3 +1) - 5))*(Team!$H$29/10), 0) -> 0 | Y3: =IF(AND(R3>=6, $A$1 <6, Q3<=6), ((K3-(T3+U3+V3+W3+X3))/ ((R3 +1) - 6))*(Team!$H$30/10), 0) -> 0 | AC3: =(H3-J3)/H3 -> 0 | AD3: =IF(AC3=1, G3,0) -> 0
C4: GRID IDC - BAU 2022.06 Release (June 2022) | G4: 8 | H4: 1.6 | I4: =VLOOKUP(H4,$AF$3:$AG$156,2,FALSE) -> 8 | J4: 1.6 | K4: =IF(J4 > 0, VLOOKUP(J4,$AF$3:$AG$103,2,FALSE),0) -> 8 | M4: New | N4: Commit | O4: BAU | P4: S | Q4: 1 | R4: 4 | S4: =(R4+1) - 1 -> 4 | T4: =IF(AND(R4>=1, $A$1 <=1,Q4<=1), (K4/ ((R4 +1) - 1))*(Team!$H$25/10), 0) -> 2 | U4: =IF(AND(R4>=2, $A$1 <=2, Q4<=2), ((K4-T4)/ ((R4 +1) - 2))*(Team!$H$26/10), 0) -> 2 | V4: =IF(AND(R4>=3, $A$1 <=3, Q4<=3), ((K4-(T4+U4))/ ((R4 +1) - 3))*(Team!$H$27/10), 0) -> 2 | W4: =IF(AND(R4>=4, $A$1 <=4, Q4<=4), ((K4-(T4+U4+V4))/ ((R4 +1) - 4))*(Team!$H$28/10), 0) -> 2 | X4: =IF(AND(R4>=5, $A$1 <5, Q4<=5), ((K4-(T4+U4+V4+W4))/ ((R4 +1) - 5))*(Team!$H$29/10), 0) -> 0 | Y4: =IF(AND(R4>=6, $A$1 <6, Q4<=6), ((K4-(T4+U4+V4+W4+X4))/ ((R4 +1) - 6))*(Team!$H$30/10), 0) -> 0 | AC4: =(H4-J4)/H4 -> 0 | AD4: =IF(AC4=1, G4,0) -> 0
C5: GRID IDC - BAU 2022.07 Release (July 2022) | G5: 8 | H5: 1.6 | I5: =VLOOKUP(H5,$AF$3:$AG$156,2,FALSE) -> 8 | J5: 1.6 | K5: =IF(J5 > 0, VLOOKUP(J5,$AF$3:$AG$103,2,FALSE),0) -> 8 | M5: New | N5: Commit | O5: BAU | P5: S | Q5: 3 | R5: 6 | S5: =(R5+1) - 1 -> 6 | T5: =IF(AND(R5>=1, $A$1 <=1,Q5<=1), (K5/ ((R5 +1) - 1))*(Team!$H$25/10), 0) -> 0 | U5: =IF(AND(R5>=2, $A$1 <=2, Q5<=2), ((K5-T5)/ ((R5 +1) - 2))*(Team!$H$26/10), 0) -> 0 | V5: =IF(AND(R5>=3, $A$1 <=3, Q5<=3), ((K5-(T5+U5))/ ((R5 +1) - 3))*(Team!$H$27/10), 0) -> 2 | W5: =IF(AND(R5>=4, $A$1 <=4, Q5<=4), ((K5-(T5+U5+V5))/ ((R5 +1) - 4))*(Team!$H$28/10), 0) -> 2 | X5: =IF(AND(R5>=5, $A$1 <5, Q5<=5), ((K5-(T5+U5+V5+W5))/ ((R5 +1) - 5))*(Team!$H$29/10), 0) -> 2 | Y5: =IF(AND(R5>=6, $A$1 <6, Q5<=6), ((K5-(T5+U5+V5+W5+X5))/ ((R5 +1) - 6))*(Team!$H$30/10), 0) -> 2 | AC5: =(H5-J5)/H5 -> 0 | AD5: =IF(AC5=1, G5,0) -> 0
C6: GRID IDC - BAU 2022.08 Release (August 2022) | G6: 8 | H6: 1 | I6: =VLOOKUP(H6,$AF$3:$AG$156,2,FALSE) -> 5 | J6: 1 | K6: =IF(J6 > 0, VLOOKUP(J6,$AF$3:$AG$103,2,FALSE),0) -> 5 | M6: New | N6: Commit | O6: BAU | P6: S | Q6: 5 | R6: 5 | S6: =(R6+1) - 1 -> 5 | T6: =IF(AND(R6>=1, $A$1 <=1,Q6<=1), (K6/ ((R6 +1) - 1))*(Team!$H$25/10), 0) -> 0 | U6: =IF(AND(R6>=2, $A$1 <=2, Q6<=2), ((K6-T6)/ ((R6 +1) - 2))*(Team!$H$26/10), 0) -> 0 | V6: =IF(AND(R6>=3, $A$1 <=3, Q6<=3), ((K6-(T6+U6))/ ((R6 +1) - 3))*(Team!$H$27/10), 0) -> 0 | W6: =IF(AND(R6>=4, $A$1 <=4, Q6<=4), ((K6-(T6+U6+V6))/ ((R6 +1) - 4))*(Team!$H$28/10), 0) -> 0 | X6: =IF(AND(R6>=5, $A$1 <5, Q6<=5), ((K6-(T6+U6+V6+W6))/ ((R6 +1) - 5))*(Team!$H$29/10), 0) -> 5 | Y6: =IF(AND(R6>=6, $A$1 <6, Q6<=6), ((K6-(T6+U6+V6+W6+X6))/ ((R6 +1) - 6))*(Team!$H$30/10), 0) -> 0 | AC6: =(H6-J6)/H6 -> 0 | AD6: =IF(AC6=1, G6,0) -> 0
C7: GRID - BAU 2022.05 Release (May 2022) | G7: 9 | H7: 1.6 | I7: =VLOOKUP(H7,$AF$3:$AG$156,2,FALSE) -> 8 | J7: 1.6 | K7: =IF(J7 > 0, VLOOKUP(J7,$AF$3:$AG$103,2,FALSE),0) -> 8 | M7: New | N7: Commit | O7: BAU | P7: S | Q7: 1 | R7: 2 | S7: =(R7+1) - 1 -> 2 | T7: =IF(AND(R7>=1, $A$1 <=1,Q7<=1), (K7/ ((R7 +1) - 1))*(Team!$H$25/10), 0) -> 4 | U7: =IF(AND(R7>=2, $A$1 <=2, Q7<=2), ((K7-T7)/ ((R7 +1) - 2))*(Team!$H$26/10), 0) -> 4 | V7: =IF(AND(R7>=3, $A$1 <=3, Q7<=3), ((K7-(T7+U7))/ ((R7 +1) - 3))*(Team!$H$27/10), 0) -> 0 | W7: =IF(AND(R7>=4, $A$1 <=4, Q7<=4), ((K7-(T7+U7+V7))/ ((R7 +1) - 4))*(Team!$H$28/10), 0) -> 0 | X7: =IF(AND(R7>=5, $A$1 <5, Q7<=5), ((K7-(T7+U7+V7+W7))/ ((R7 +1) - 5))*(Team!$H$29/10), 0) -> 0 | Y7: =IF(AND(R7>=6, $A$1 <6, Q7<=6), ((K7-(T7+U7+V7+W7+X7))/ ((R7 +1) - 6))*(Team!$H$30/10), 0) -> 0 | AC7: =(H7-J7)/H7 -> 0
C8: GRID - BAU 2022.06 Release (June 2022) | G8: 9 | H8: 1.6 | I8: =VLOOKUP(H8,$AF$3:$AG$156,2,FALSE) -> 8 | J8: 1.6 | K8: =IF(J8 > 0, VLOOKUP(J8,$AF$3:$AG$103,2,FALSE),0) -> 8 | M8: New | N8: Commit | O8: BAU | P8: S | Q8: 1 | R8: 4 | S8: =(R8+1) - 1 -> 4 | T8: =IF(AND(R8>=1, $A$1 <=1,Q8<=1), (K8/ ((R8 +1) - 1))*(Team!$H$25/10), 0) -> 2 | U8: =IF(AND(R8>=2, $A$1 <=2, Q8<=2), ((K8-T8)/ ((R8 +1) - 2))*(Team!$H$26/10), 0) -> 2 | V8: =IF(AND(R8>=3, $A$1 <=3, Q8<=3), ((K8-(T8+U8))/ ((R8 +1) - 3))*(Team!$H$27/10), 0) -> 2 | W8: =IF(AND(R8>=4, $A$1 <=4, Q8<=4), ((K8-(T8+U8+V8))/ ((R8 +1) - 4))*(Team!$H$28/10), 0) -> 2 | X8: =IF(AND(R8>=5, $A$1 <5, Q8<=5), ((K8-(T8+U8+V8+W8))/ ((R8 +1) - 5))*(Team!$H$29/10), 0) -> 0 | Y8: =IF(AND(R8>=6, $A$1 <6, Q8<=6), ((K8-(T8+U8+V8+W8+X8))/ ((R8 +1) - 6))*(Team!$H$30/10), 0) -> 0 | AC8: =(H8-J8)/H8 -> 0
C9: GRID - BAU 2022.07 Release (July 2022) | G9: 9 | H9: 1.6 | I9: =VLOOKUP(H9,$AF$3:$AG$156,2,FALSE) -> 8 | J9: 1.6 | K9: =IF(J9 > 0, VLOOKUP(J9,$AF$3:$AG$103,2,FALSE),0) -> 8 | M9: New | N9: Commit | O9: BAU | P9: S | Q9: 3 | R9: 6 | S9: =(R9+1) - 1 -> 6 | T9: =IF(AND(R9>=1, $A$1 <=1,Q9<=1), (K9/ ((R9 +1) - 1))*(Team!$H$25/10), 0) -> 0 | U9: =IF(AND(R9>=2, $A$1 <=2, Q9<=2), ((K9-T9)/ ((R9 +1) - 2))*(Team!$H$26/10), 0) -> 0 | V9: =IF(AND(R9>=3, $A$1 <=3, Q9<=3), ((K9-(T9+U9))/ ((R9 +1) - 3))*(Team!$H$27/10), 0) -> 2 | W9: =IF(AND(R9>=4, $A$1 <=4, Q9<=4), ((K9-(T9+U9+V9))/ ((R9 +1) - 4))*(Team!$H$28/10), 0) -> 2 | X9: =IF(AND(R9>=5, $A$1 <5, Q9<=5), ((K9-(T9+U9+V9+W9))/ ((R9 +1) - 5))*(Team!$H$29/10), 0) -> 2 | Y9: =IF(AND(R9>=6, $A$1 <6, Q9<=6), ((K9-(T9+U9+V9+W9+X9))/ ((R9 +1) - 6))*(Team!$H$30/10), 0) -> 2 | AC9: =(H9-J9)/H9 -> 0 | AD9: =IF(AC9=1, G9,0) -> 0
C10: GRID - BAU 2022.08 Release (August 2022) | G10: 9 | H10: 1 | I10: =VLOOKUP(H10,$AF$3:$AG$156,2,FALSE) -> 5 | J10: 1 | K10: =IF(J10 > 0, VLOOKUP(J10,$AF$3:$AG$103,2,FALSE),0) -> 5 | M10: New | N10: Commit | O10: BAU | P10: S | Q10: 5 | R10: 6 | S10: =(R10+1) - 1 -> 6 | T10: =IF(AND(R10>=1, $A$1 <=1,Q10<=1), (K10/ ((R10 +1) - 1))*(Team!$H$25/10), 0) -> 0 | U10: =IF(AND(R10>=2, $A$1 <=2, Q10<=2), ((K10-T10)/ ((R10 +1) - 2))*(Team!$H$26/10), 0) -> 0 | V10: =IF(AND(R10>=3, $A$1 <=3, Q10<=3), ((K10-(T10+U10))/ ((R10 +1) - 3))*(Team!$H$27/10), 0) -> 0 | W10: =IF(AND(R10>=4, $A$1 <=4, Q10<=4), ((K10-(T10+U10+V10))/ ((R10 +1) - 4))*(Team!$H$28/10), 0) -> 0 | X10: =IF(AND(R10>=5, $A$1 <5, Q10<=5), ((K10-(T10+U10+V10+W10))/ ((R10 +1) - 5))*(Team!$H$29/10), 0) -> 2.5 | Y10: =IF(AND(R10>=6, $A$1 <6, Q10<=6), ((K10-(T10+U10+V10+W10+X10))/ ((R10 +1) - 6))*(Team!$H$30/10), 0) -> 2.5 | AC10: =(H10-J10)/H10 -> 0 | AD10: =IF(AC10=1, G10,0) -> 0
